[
    {
        "content": "<p>Has anyone seen this error while trying to <code>./x.py test</code> the current master (actually, I've had this issue for a few days now)?</p>\n<p><code>Compiling chalk-solve v0.32.0\nthread 'rustc' panicked at 'index out of bounds: the len is 4067 but the index is 4067', /home/dani/rust/compiler/rustc_serialize/src/opaque.rs:240:21</code></p>",
        "id": 212961029,
        "sender_full_name": "Dániel Buga",
        "timestamp": 1602414420
    },
    {
        "content": "<p>Do you have incremental enabled? If so try removing the incremental caches.</p>",
        "id": 212961083,
        "sender_full_name": "bjorn3",
        "timestamp": 1602414495
    },
    {
        "content": "<p>Hmm, I don't think I have it enabled, but a <code>clean</code> did solve this. Thanks!</p>",
        "id": 212961524,
        "sender_full_name": "Dániel Buga",
        "timestamp": 1602415405
    },
    {
        "content": "<p>Side note: a full x.py test is almost never what you want, they take forever and CI will run them anyway.</p>",
        "id": 212963509,
        "sender_full_name": "Joshua Nelson",
        "timestamp": 1602419023
    }
]